{
 "cells": [
  {
   "cell_type": "code",
   "execution_count": 3,
   "metadata": {},
   "outputs": [
    {
     "name": "stdout",
     "output_type": "stream",
     "text": [
      " * Serving Flask app \"__main__\" (lazy loading)\n",
      " * Environment: production\n",
      "   WARNING: This is a development server. Do not use it in a production deployment.\n",
      "   Use a production WSGI server instead.\n",
      " * Debug mode: off\n"
     ]
    },
    {
     "name": "stderr",
     "output_type": "stream",
     "text": [
      " * Running on http://127.0.0.1:5000/ (Press CTRL+C to quit)\n",
      "127.0.0.1 - - [25/Jan/2021 21:10:09] \"\u001b[37mGET / HTTP/1.1\u001b[0m\" 200 -\n",
      "127.0.0.1 - - [25/Jan/2021 21:10:09] \"\u001b[33mGET /home.jpg HTTP/1.1\u001b[0m\" 404 -\n",
      "127.0.0.1 - - [25/Jan/2021 21:10:12] \"\u001b[37mGET / HTTP/1.1\u001b[0m\" 200 -\n",
      "127.0.0.1 - - [25/Jan/2021 21:10:12] \"\u001b[33mGET /home.jpg HTTP/1.1\u001b[0m\" 404 -\n",
      "[2021-01-25 21:10:13,656] ERROR in app: Exception on /predict [POST]\n",
      "Traceback (most recent call last):\n",
      "  File \"c:\\users\\charudatta\\appdata\\local\\programs\\python\\python39\\lib\\site-packages\\flask\\app.py\", line 2117, in make_response\n",
      "    rv = self.response_class.force_type(rv, request.environ)\n",
      "  File \"c:\\users\\charudatta\\appdata\\local\\programs\\python\\python39\\lib\\site-packages\\werkzeug\\wrappers\\base_response.py\", line 269, in force_type\n",
      "    response = BaseResponse(*_run_wsgi_app(response, environ))\n",
      "  File \"c:\\users\\charudatta\\appdata\\local\\programs\\python\\python39\\lib\\site-packages\\werkzeug\\test.py\", line 1096, in run_wsgi_app\n",
      "    app_rv = app(environ, start_response)\n",
      "  File \"c:\\users\\charudatta\\appdata\\local\\programs\\python\\python39\\lib\\site-packages\\werkzeug\\local.py\", line 375, in <lambda>\n",
      "    __call__ = lambda x, *a, **kw: x._get_current_object()(*a, **kw)\n",
      "TypeError: 'Request' object is not callable\n",
      "\n",
      "During handling of the above exception, another exception occurred:\n",
      "\n",
      "Traceback (most recent call last):\n",
      "  File \"c:\\users\\charudatta\\appdata\\local\\programs\\python\\python39\\lib\\site-packages\\flask\\app.py\", line 2447, in wsgi_app\n",
      "    response = self.full_dispatch_request()\n",
      "  File \"c:\\users\\charudatta\\appdata\\local\\programs\\python\\python39\\lib\\site-packages\\flask\\app.py\", line 1953, in full_dispatch_request\n",
      "    return self.finalize_request(rv)\n",
      "  File \"c:\\users\\charudatta\\appdata\\local\\programs\\python\\python39\\lib\\site-packages\\flask\\app.py\", line 1968, in finalize_request\n",
      "    response = self.make_response(rv)\n",
      "  File \"c:\\users\\charudatta\\appdata\\local\\programs\\python\\python39\\lib\\site-packages\\flask\\app.py\", line 2125, in make_response\n",
      "    reraise(TypeError, new_error, sys.exc_info()[2])\n",
      "  File \"c:\\users\\charudatta\\appdata\\local\\programs\\python\\python39\\lib\\site-packages\\flask\\_compat.py\", line 38, in reraise\n",
      "    raise value.with_traceback(tb)\n",
      "  File \"c:\\users\\charudatta\\appdata\\local\\programs\\python\\python39\\lib\\site-packages\\flask\\app.py\", line 2117, in make_response\n",
      "    rv = self.response_class.force_type(rv, request.environ)\n",
      "  File \"c:\\users\\charudatta\\appdata\\local\\programs\\python\\python39\\lib\\site-packages\\werkzeug\\wrappers\\base_response.py\", line 269, in force_type\n",
      "    response = BaseResponse(*_run_wsgi_app(response, environ))\n",
      "  File \"c:\\users\\charudatta\\appdata\\local\\programs\\python\\python39\\lib\\site-packages\\werkzeug\\test.py\", line 1096, in run_wsgi_app\n",
      "    app_rv = app(environ, start_response)\n",
      "  File \"c:\\users\\charudatta\\appdata\\local\\programs\\python\\python39\\lib\\site-packages\\werkzeug\\local.py\", line 375, in <lambda>\n",
      "    __call__ = lambda x, *a, **kw: x._get_current_object()(*a, **kw)\n",
      "TypeError: 'Request' object is not callable\n",
      "The view function did not return a valid response. The return type must be a string, dict, tuple, Response instance, or WSGI callable, but it was a LocalProxy.\n",
      "127.0.0.1 - - [25/Jan/2021 21:10:13] \"\u001b[35m\u001b[1mPOST /predict HTTP/1.1\u001b[0m\" 500 -\n",
      "[2021-01-25 21:10:41,498] ERROR in app: Exception on /predict [POST]\n",
      "Traceback (most recent call last):\n",
      "  File \"c:\\users\\charudatta\\appdata\\local\\programs\\python\\python39\\lib\\site-packages\\flask\\app.py\", line 2117, in make_response\n",
      "    rv = self.response_class.force_type(rv, request.environ)\n",
      "  File \"c:\\users\\charudatta\\appdata\\local\\programs\\python\\python39\\lib\\site-packages\\werkzeug\\wrappers\\base_response.py\", line 269, in force_type\n",
      "    response = BaseResponse(*_run_wsgi_app(response, environ))\n",
      "  File \"c:\\users\\charudatta\\appdata\\local\\programs\\python\\python39\\lib\\site-packages\\werkzeug\\test.py\", line 1096, in run_wsgi_app\n",
      "    app_rv = app(environ, start_response)\n",
      "  File \"c:\\users\\charudatta\\appdata\\local\\programs\\python\\python39\\lib\\site-packages\\werkzeug\\local.py\", line 375, in <lambda>\n",
      "    __call__ = lambda x, *a, **kw: x._get_current_object()(*a, **kw)\n",
      "TypeError: 'Request' object is not callable\n",
      "\n",
      "During handling of the above exception, another exception occurred:\n",
      "\n",
      "Traceback (most recent call last):\n",
      "  File \"c:\\users\\charudatta\\appdata\\local\\programs\\python\\python39\\lib\\site-packages\\flask\\app.py\", line 2447, in wsgi_app\n",
      "    response = self.full_dispatch_request()\n",
      "  File \"c:\\users\\charudatta\\appdata\\local\\programs\\python\\python39\\lib\\site-packages\\flask\\app.py\", line 1953, in full_dispatch_request\n",
      "    return self.finalize_request(rv)\n",
      "  File \"c:\\users\\charudatta\\appdata\\local\\programs\\python\\python39\\lib\\site-packages\\flask\\app.py\", line 1968, in finalize_request\n",
      "    response = self.make_response(rv)\n",
      "  File \"c:\\users\\charudatta\\appdata\\local\\programs\\python\\python39\\lib\\site-packages\\flask\\app.py\", line 2125, in make_response\n",
      "    reraise(TypeError, new_error, sys.exc_info()[2])\n",
      "  File \"c:\\users\\charudatta\\appdata\\local\\programs\\python\\python39\\lib\\site-packages\\flask\\_compat.py\", line 38, in reraise\n",
      "    raise value.with_traceback(tb)\n",
      "  File \"c:\\users\\charudatta\\appdata\\local\\programs\\python\\python39\\lib\\site-packages\\flask\\app.py\", line 2117, in make_response\n",
      "    rv = self.response_class.force_type(rv, request.environ)\n",
      "  File \"c:\\users\\charudatta\\appdata\\local\\programs\\python\\python39\\lib\\site-packages\\werkzeug\\wrappers\\base_response.py\", line 269, in force_type\n",
      "    response = BaseResponse(*_run_wsgi_app(response, environ))\n",
      "  File \"c:\\users\\charudatta\\appdata\\local\\programs\\python\\python39\\lib\\site-packages\\werkzeug\\test.py\", line 1096, in run_wsgi_app\n",
      "    app_rv = app(environ, start_response)\n",
      "  File \"c:\\users\\charudatta\\appdata\\local\\programs\\python\\python39\\lib\\site-packages\\werkzeug\\local.py\", line 375, in <lambda>\n",
      "    __call__ = lambda x, *a, **kw: x._get_current_object()(*a, **kw)\n",
      "TypeError: 'Request' object is not callable\n",
      "The view function did not return a valid response. The return type must be a string, dict, tuple, Response instance, or WSGI callable, but it was a LocalProxy.\n",
      "127.0.0.1 - - [25/Jan/2021 21:10:41] \"\u001b[35m\u001b[1mPOST /predict HTTP/1.1\u001b[0m\" 500 -\n",
      "127.0.0.1 - - [25/Jan/2021 21:10:43] \"\u001b[37mGET / HTTP/1.1\u001b[0m\" 200 -\n",
      "127.0.0.1 - - [25/Jan/2021 21:10:43] \"\u001b[33mGET /home.jpg HTTP/1.1\u001b[0m\" 404 -\n",
      "[2021-01-25 21:10:44,836] ERROR in app: Exception on /predict [POST]\n",
      "Traceback (most recent call last):\n",
      "  File \"c:\\users\\charudatta\\appdata\\local\\programs\\python\\python39\\lib\\site-packages\\flask\\app.py\", line 2117, in make_response\n",
      "    rv = self.response_class.force_type(rv, request.environ)\n",
      "  File \"c:\\users\\charudatta\\appdata\\local\\programs\\python\\python39\\lib\\site-packages\\werkzeug\\wrappers\\base_response.py\", line 269, in force_type\n",
      "    response = BaseResponse(*_run_wsgi_app(response, environ))\n",
      "  File \"c:\\users\\charudatta\\appdata\\local\\programs\\python\\python39\\lib\\site-packages\\werkzeug\\test.py\", line 1096, in run_wsgi_app\n",
      "    app_rv = app(environ, start_response)\n",
      "  File \"c:\\users\\charudatta\\appdata\\local\\programs\\python\\python39\\lib\\site-packages\\werkzeug\\local.py\", line 375, in <lambda>\n",
      "    __call__ = lambda x, *a, **kw: x._get_current_object()(*a, **kw)\n",
      "TypeError: 'Request' object is not callable\n",
      "\n",
      "During handling of the above exception, another exception occurred:\n",
      "\n",
      "Traceback (most recent call last):\n",
      "  File \"c:\\users\\charudatta\\appdata\\local\\programs\\python\\python39\\lib\\site-packages\\flask\\app.py\", line 2447, in wsgi_app\n",
      "    response = self.full_dispatch_request()\n",
      "  File \"c:\\users\\charudatta\\appdata\\local\\programs\\python\\python39\\lib\\site-packages\\flask\\app.py\", line 1953, in full_dispatch_request\n",
      "    return self.finalize_request(rv)\n",
      "  File \"c:\\users\\charudatta\\appdata\\local\\programs\\python\\python39\\lib\\site-packages\\flask\\app.py\", line 1968, in finalize_request\n",
      "    response = self.make_response(rv)\n",
      "  File \"c:\\users\\charudatta\\appdata\\local\\programs\\python\\python39\\lib\\site-packages\\flask\\app.py\", line 2125, in make_response\n",
      "    reraise(TypeError, new_error, sys.exc_info()[2])\n",
      "  File \"c:\\users\\charudatta\\appdata\\local\\programs\\python\\python39\\lib\\site-packages\\flask\\_compat.py\", line 38, in reraise\n",
      "    raise value.with_traceback(tb)\n",
      "  File \"c:\\users\\charudatta\\appdata\\local\\programs\\python\\python39\\lib\\site-packages\\flask\\app.py\", line 2117, in make_response\n",
      "    rv = self.response_class.force_type(rv, request.environ)\n",
      "  File \"c:\\users\\charudatta\\appdata\\local\\programs\\python\\python39\\lib\\site-packages\\werkzeug\\wrappers\\base_response.py\", line 269, in force_type\n",
      "    response = BaseResponse(*_run_wsgi_app(response, environ))\n",
      "  File \"c:\\users\\charudatta\\appdata\\local\\programs\\python\\python39\\lib\\site-packages\\werkzeug\\test.py\", line 1096, in run_wsgi_app\n",
      "    app_rv = app(environ, start_response)\n",
      "  File \"c:\\users\\charudatta\\appdata\\local\\programs\\python\\python39\\lib\\site-packages\\werkzeug\\local.py\", line 375, in <lambda>\n",
      "    __call__ = lambda x, *a, **kw: x._get_current_object()(*a, **kw)\n",
      "TypeError: 'Request' object is not callable\n",
      "The view function did not return a valid response. The return type must be a string, dict, tuple, Response instance, or WSGI callable, but it was a LocalProxy.\n"
     ]
    },
    {
     "name": "stderr",
     "output_type": "stream",
     "text": [
      "127.0.0.1 - - [25/Jan/2021 21:10:44] \"\u001b[35m\u001b[1mPOST /predict HTTP/1.1\u001b[0m\" 500 -\n",
      "[2021-01-25 21:10:47,405] ERROR in app: Exception on /predict [POST]\n",
      "Traceback (most recent call last):\n",
      "  File \"c:\\users\\charudatta\\appdata\\local\\programs\\python\\python39\\lib\\site-packages\\flask\\app.py\", line 2117, in make_response\n",
      "    rv = self.response_class.force_type(rv, request.environ)\n",
      "  File \"c:\\users\\charudatta\\appdata\\local\\programs\\python\\python39\\lib\\site-packages\\werkzeug\\wrappers\\base_response.py\", line 269, in force_type\n",
      "    response = BaseResponse(*_run_wsgi_app(response, environ))\n",
      "  File \"c:\\users\\charudatta\\appdata\\local\\programs\\python\\python39\\lib\\site-packages\\werkzeug\\test.py\", line 1096, in run_wsgi_app\n",
      "    app_rv = app(environ, start_response)\n",
      "  File \"c:\\users\\charudatta\\appdata\\local\\programs\\python\\python39\\lib\\site-packages\\werkzeug\\local.py\", line 375, in <lambda>\n",
      "    __call__ = lambda x, *a, **kw: x._get_current_object()(*a, **kw)\n",
      "TypeError: 'Request' object is not callable\n",
      "\n",
      "During handling of the above exception, another exception occurred:\n",
      "\n",
      "Traceback (most recent call last):\n",
      "  File \"c:\\users\\charudatta\\appdata\\local\\programs\\python\\python39\\lib\\site-packages\\flask\\app.py\", line 2447, in wsgi_app\n",
      "    response = self.full_dispatch_request()\n",
      "  File \"c:\\users\\charudatta\\appdata\\local\\programs\\python\\python39\\lib\\site-packages\\flask\\app.py\", line 1953, in full_dispatch_request\n",
      "    return self.finalize_request(rv)\n",
      "  File \"c:\\users\\charudatta\\appdata\\local\\programs\\python\\python39\\lib\\site-packages\\flask\\app.py\", line 1968, in finalize_request\n",
      "    response = self.make_response(rv)\n",
      "  File \"c:\\users\\charudatta\\appdata\\local\\programs\\python\\python39\\lib\\site-packages\\flask\\app.py\", line 2125, in make_response\n",
      "    reraise(TypeError, new_error, sys.exc_info()[2])\n",
      "  File \"c:\\users\\charudatta\\appdata\\local\\programs\\python\\python39\\lib\\site-packages\\flask\\_compat.py\", line 38, in reraise\n",
      "    raise value.with_traceback(tb)\n",
      "  File \"c:\\users\\charudatta\\appdata\\local\\programs\\python\\python39\\lib\\site-packages\\flask\\app.py\", line 2117, in make_response\n",
      "    rv = self.response_class.force_type(rv, request.environ)\n",
      "  File \"c:\\users\\charudatta\\appdata\\local\\programs\\python\\python39\\lib\\site-packages\\werkzeug\\wrappers\\base_response.py\", line 269, in force_type\n",
      "    response = BaseResponse(*_run_wsgi_app(response, environ))\n",
      "  File \"c:\\users\\charudatta\\appdata\\local\\programs\\python\\python39\\lib\\site-packages\\werkzeug\\test.py\", line 1096, in run_wsgi_app\n",
      "    app_rv = app(environ, start_response)\n",
      "  File \"c:\\users\\charudatta\\appdata\\local\\programs\\python\\python39\\lib\\site-packages\\werkzeug\\local.py\", line 375, in <lambda>\n",
      "    __call__ = lambda x, *a, **kw: x._get_current_object()(*a, **kw)\n",
      "TypeError: 'Request' object is not callable\n",
      "The view function did not return a valid response. The return type must be a string, dict, tuple, Response instance, or WSGI callable, but it was a LocalProxy.\n",
      "127.0.0.1 - - [25/Jan/2021 21:10:47] \"\u001b[35m\u001b[1mPOST /predict HTTP/1.1\u001b[0m\" 500 -\n"
     ]
    }
   ],
   "source": [
    "import numpy as np\n",
    "import pandas as pd\n",
    "from flask import Flask, request, render_template\n",
    "from joblib import dump, load\n",
    "\n",
    "import requests\n",
    "\n",
    "model = load('VC_Awsome.joblib')\n",
    "df = pd.DataFrame()\n",
    "\n",
    "app = Flask(__name__,template_folder='templates') \n",
    "\n",
    "@app.route('/') \n",
    "# ‘/’ URL is bound with hello_world() function. \n",
    "def hello_world(): \n",
    "    return render_template('index.html')\n",
    "\n",
    "@app.route('/predict',methods=['POST'])\n",
    "def predict():\n",
    "    \n",
    " global df\n",
    " return df\n",
    "\n",
    "if __name__ == '__main__': \n",
    "    app.run() \n"
   ]
  },
  {
   "cell_type": "code",
   "execution_count": null,
   "metadata": {},
   "outputs": [],
   "source": []
  },
  {
   "cell_type": "code",
   "execution_count": null,
   "metadata": {},
   "outputs": [],
   "source": []
  }
 ],
 "metadata": {
  "kernelspec": {
   "display_name": "Python 3",
   "language": "python",
   "name": "python3"
  },
  "language_info": {
   "codemirror_mode": {
    "name": "ipython",
    "version": 3
   },
   "file_extension": ".py",
   "mimetype": "text/x-python",
   "name": "python",
   "nbconvert_exporter": "python",
   "pygments_lexer": "ipython3",
   "version": "3.9.1"
  }
 },
 "nbformat": 4,
 "nbformat_minor": 4
}
